<?xml version="1.0"?>
<robot xmlns:xacro="http://www.ros.org/wiki/xacro">
    <xacro:macro name="insert_robot" params="prefix">
        <link name="base_footprint"/>
        <link name="base_link"/>

        <joint name="base_link_fixed" type="fixed">
            <parent link="base_footprint"/>
            <child link="base_link"/>
            <origin xyz="0 0 0" rpy="0 0 0"/>
        </joint>

        <link name="l_wheel"/>
        <link name="r_wheel"/>

        <joint name="l_wheel_joint" type="continuous">
            <parent link="base_link"/>
            <child link="l_wheel"/>
            <axis xyz="0 1 0"/>
            <origin xyz="0 0 0" rpy="0 0 0"/>
        </joint>

        <joint name="r_wheel_joint" type="continuous">
            <parent link="base_link"/>
            <child link="r_wheel"/>
            <axis xyz="0 1 0"/>
            <origin xyz="0 0 0" rpy="0 0 0"/>
        </joint>
    </xacro:macro>
</robot>